Traceback (most recent call last):
  File "/home/john/anaconda3/envs/bcd/lib/python3.10/site-packages/jupyter_cache/executors/utils.py", line 58, in single_nb_execution
    executenb(
  File "/home/john/anaconda3/envs/bcd/lib/python3.10/site-packages/nbclient/client.py", line 1305, in execute
    return NotebookClient(nb=nb, resources=resources, km=km, **kwargs).execute()
  File "/home/john/anaconda3/envs/bcd/lib/python3.10/site-packages/jupyter_core/utils/__init__.py", line 166, in wrapped
    return loop.run_until_complete(inner)
  File "/home/john/anaconda3/envs/bcd/lib/python3.10/asyncio/base_events.py", line 649, in run_until_complete
    return future.result()
  File "/home/john/anaconda3/envs/bcd/lib/python3.10/site-packages/nbclient/client.py", line 705, in async_execute
    await self.async_execute_cell(
  File "/home/john/anaconda3/envs/bcd/lib/python3.10/site-packages/nbclient/client.py", line 1058, in async_execute_cell
    await self._check_raise_for_error(cell, cell_index, exec_reply)
  File "/home/john/anaconda3/envs/bcd/lib/python3.10/site-packages/nbclient/client.py", line 914, in _check_raise_for_error
    raise CellExecutionError.from_cell_and_msg(cell, exec_reply_content)
nbclient.exceptions.CellExecutionError: An error occurred while executing the following cell:
------------------
df = ds.as_df()
print(f"All images are of the {df['photometric_interpretation'].unique()[0]} representation.")
print(f"All images have {df['samples_per_pixel'].unique()[0]} sample(s) per pixel.")
fig, ax = plt.subplots(figsize=(12,4))
ds.plot.countplot(x='bits', ax=ax, hue='series_description', title ="CBIS-DDSM Image Bit Depth", plot_counts=False)


------------------


[0;31m---------------------------------------------------------------------------[0m
[0;31mNameError[0m                                 Traceback (most recent call last)
Cell [0;32mIn[77], line 1[0m
[0;32m----> 1[0m df [38;5;241m=[39m [43mds[49m[38;5;241m.[39mas_df()
[1;32m      2[0m [38;5;28mprint[39m([38;5;124mf[39m[38;5;124m"[39m[38;5;124mAll images are of the [39m[38;5;132;01m{[39;00mdf[[38;5;124m'[39m[38;5;124mphotometric_interpretation[39m[38;5;124m'[39m][38;5;241m.[39munique()[[38;5;241m0[39m][38;5;132;01m}[39;00m[38;5;124m representation.[39m[38;5;124m"[39m)
[1;32m      3[0m [38;5;28mprint[39m([38;5;124mf[39m[38;5;124m"[39m[38;5;124mAll images have [39m[38;5;132;01m{[39;00mdf[[38;5;124m'[39m[38;5;124msamples_per_pixel[39m[38;5;124m'[39m][38;5;241m.[39munique()[[38;5;241m0[39m][38;5;132;01m}[39;00m[38;5;124m sample(s) per pixel.[39m[38;5;124m"[39m)

[0;31mNameError[0m: name 'ds' is not defined

