Traceback (most recent call last):
  File "/home/john/anaconda3/envs/bcd/lib/python3.10/site-packages/jupyter_cache/executors/utils.py", line 58, in single_nb_execution
    executenb(
  File "/home/john/anaconda3/envs/bcd/lib/python3.10/site-packages/nbclient/client.py", line 1204, in execute
    return NotebookClient(nb=nb, resources=resources, km=km, **kwargs).execute()
  File "/home/john/anaconda3/envs/bcd/lib/python3.10/site-packages/nbclient/util.py", line 84, in wrapped
    return just_run(coro(*args, **kwargs))
  File "/home/john/anaconda3/envs/bcd/lib/python3.10/site-packages/nbclient/util.py", line 62, in just_run
    return loop.run_until_complete(coro)
  File "/home/john/anaconda3/envs/bcd/lib/python3.10/asyncio/base_events.py", line 649, in run_until_complete
    return future.result()
  File "/home/john/anaconda3/envs/bcd/lib/python3.10/site-packages/nbclient/client.py", line 663, in async_execute
    await self.async_execute_cell(
  File "/home/john/anaconda3/envs/bcd/lib/python3.10/site-packages/nbclient/client.py", line 965, in async_execute_cell
    await self._check_raise_for_error(cell, cell_index, exec_reply)
  File "/home/john/anaconda3/envs/bcd/lib/python3.10/site-packages/nbclient/client.py", line 862, in _check_raise_for_error
    raise CellExecutionError.from_cell_and_msg(cell, exec_reply_content)
nbclient.exceptions.CellExecutionError: An error occurred while executing the following cell:
------------------
df_full_desc = pd.DataFrame()
df_full_desc['smallest_pixel_value'] = df_full['min_pixel_value'].describe().T
df_full_desc['largest_pixel_value'] = df_full['largest_image_pixel'].describe().T
df_full_desc['range_pixel_values'] = df_full['range_pixel_values'].describe().T
df_full_desc.T
------------------

[0;31m---------------------------------------------------------------------------[0m
[0;31mKeyError[0m                                  Traceback (most recent call last)
File [0;32m~/anaconda3/envs/bcd/lib/python3.10/site-packages/pandas/core/indexes/base.py:3790[0m, in [0;36mIndex.get_loc[0;34m(self, key)[0m
[1;32m   3789[0m [38;5;28;01mtry[39;00m:
[0;32m-> 3790[0m     [38;5;28;01mreturn[39;00m [38;5;28;43mself[39;49m[38;5;241;43m.[39;49m[43m_engine[49m[38;5;241;43m.[39;49m[43mget_loc[49m[43m([49m[43mcasted_key[49m[43m)[49m
[1;32m   3791[0m [38;5;28;01mexcept[39;00m [38;5;167;01mKeyError[39;00m [38;5;28;01mas[39;00m err:

File [0;32mindex.pyx:152[0m, in [0;36mpandas._libs.index.IndexEngine.get_loc[0;34m()[0m

File [0;32mindex.pyx:181[0m, in [0;36mpandas._libs.index.IndexEngine.get_loc[0;34m()[0m

File [0;32mpandas/_libs/hashtable_class_helper.pxi:7080[0m, in [0;36mpandas._libs.hashtable.PyObjectHashTable.get_item[0;34m()[0m

File [0;32mpandas/_libs/hashtable_class_helper.pxi:7088[0m, in [0;36mpandas._libs.hashtable.PyObjectHashTable.get_item[0;34m()[0m

[0;31mKeyError[0m: 'largest_image_pixel'

The above exception was the direct cause of the following exception:

[0;31mKeyError[0m                                  Traceback (most recent call last)
Cell [0;32mIn[87], line 3[0m
[1;32m      1[0m df_full_desc [38;5;241m=[39m pd[38;5;241m.[39mDataFrame()
[1;32m      2[0m df_full_desc[[38;5;124m'[39m[38;5;124msmallest_pixel_value[39m[38;5;124m'[39m] [38;5;241m=[39m df_full[[38;5;124m'[39m[38;5;124mmin_pixel_value[39m[38;5;124m'[39m][38;5;241m.[39mdescribe()[38;5;241m.[39mT
[0;32m----> 3[0m df_full_desc[[38;5;124m'[39m[38;5;124mlargest_pixel_value[39m[38;5;124m'[39m] [38;5;241m=[39m [43mdf_full[49m[43m[[49m[38;5;124;43m'[39;49m[38;5;124;43mlargest_image_pixel[39;49m[38;5;124;43m'[39;49m[43m][49m[38;5;241m.[39mdescribe()[38;5;241m.[39mT
[1;32m      4[0m df_full_desc[[38;5;124m'[39m[38;5;124mrange_pixel_values[39m[38;5;124m'[39m] [38;5;241m=[39m df_full[[38;5;124m'[39m[38;5;124mrange_pixel_values[39m[38;5;124m'[39m][38;5;241m.[39mdescribe()[38;5;241m.[39mT
[1;32m      5[0m df_full_desc[38;5;241m.[39mT

File [0;32m~/anaconda3/envs/bcd/lib/python3.10/site-packages/pandas/core/frame.py:3896[0m, in [0;36mDataFrame.__getitem__[0;34m(self, key)[0m
[1;32m   3894[0m [38;5;28;01mif[39;00m [38;5;28mself[39m[38;5;241m.[39mcolumns[38;5;241m.[39mnlevels [38;5;241m>[39m [38;5;241m1[39m:
[1;32m   3895[0m     [38;5;28;01mreturn[39;00m [38;5;28mself[39m[38;5;241m.[39m_getitem_multilevel(key)
[0;32m-> 3896[0m indexer [38;5;241m=[39m [38;5;28;43mself[39;49m[38;5;241;43m.[39;49m[43mcolumns[49m[38;5;241;43m.[39;49m[43mget_loc[49m[43m([49m[43mkey[49m[43m)[49m
[1;32m   3897[0m [38;5;28;01mif[39;00m is_integer(indexer):
[1;32m   3898[0m     indexer [38;5;241m=[39m [indexer]

File [0;32m~/anaconda3/envs/bcd/lib/python3.10/site-packages/pandas/core/indexes/base.py:3797[0m, in [0;36mIndex.get_loc[0;34m(self, key)[0m
[1;32m   3792[0m     [38;5;28;01mif[39;00m [38;5;28misinstance[39m(casted_key, [38;5;28mslice[39m) [38;5;129;01mor[39;00m (
[1;32m   3793[0m         [38;5;28misinstance[39m(casted_key, abc[38;5;241m.[39mIterable)
[1;32m   3794[0m         [38;5;129;01mand[39;00m [38;5;28many[39m([38;5;28misinstance[39m(x, [38;5;28mslice[39m) [38;5;28;01mfor[39;00m x [38;5;129;01min[39;00m casted_key)
[1;32m   3795[0m     ):
[1;32m   3796[0m         [38;5;28;01mraise[39;00m InvalidIndexError(key)
[0;32m-> 3797[0m     [38;5;28;01mraise[39;00m [38;5;167;01mKeyError[39;00m(key) [38;5;28;01mfrom[39;00m [38;5;21;01merr[39;00m
[1;32m   3798[0m [38;5;28;01mexcept[39;00m [38;5;167;01mTypeError[39;00m:
[1;32m   3799[0m     [38;5;66;03m# If we have a listlike key, _check_indexing_error will raise[39;00m
[1;32m   3800[0m     [38;5;66;03m#  InvalidIndexError. Otherwise we fall through and re-raise[39;00m
[1;32m   3801[0m     [38;5;66;03m#  the TypeError.[39;00m
[1;32m   3802[0m     [38;5;28mself[39m[38;5;241m.[39m_check_indexing_error(key)

[0;31mKeyError[0m: 'largest_image_pixel'
KeyError: 'largest_image_pixel'

