Traceback (most recent call last):
  File "/home/john/anaconda3/envs/bcd/lib/python3.10/site-packages/jupyter_cache/executors/utils.py", line 58, in single_nb_execution
    executenb(
  File "/home/john/anaconda3/envs/bcd/lib/python3.10/site-packages/nbclient/client.py", line 1204, in execute
    return NotebookClient(nb=nb, resources=resources, km=km, **kwargs).execute()
  File "/home/john/anaconda3/envs/bcd/lib/python3.10/site-packages/nbclient/util.py", line 84, in wrapped
    return just_run(coro(*args, **kwargs))
  File "/home/john/anaconda3/envs/bcd/lib/python3.10/site-packages/nbclient/util.py", line 62, in just_run
    return loop.run_until_complete(coro)
  File "/home/john/anaconda3/envs/bcd/lib/python3.10/asyncio/base_events.py", line 649, in run_until_complete
    return future.result()
  File "/home/john/anaconda3/envs/bcd/lib/python3.10/site-packages/nbclient/client.py", line 663, in async_execute
    await self.async_execute_cell(
  File "/home/john/anaconda3/envs/bcd/lib/python3.10/site-packages/nbclient/client.py", line 965, in async_execute_cell
    await self._check_raise_for_error(cell, cell_index, exec_reply)
  File "/home/john/anaconda3/envs/bcd/lib/python3.10/site-packages/nbclient/client.py", line 862, in _check_raise_for_error
    raise CellExecutionError.from_cell_and_msg(cell, exec_reply_content)
nbclient.exceptions.CellExecutionError: An error occurred while executing the following cell:
------------------
if not SETUP_COMPLETE:
    uow = container.dal.uow()
    uow.reset()
------------------

[0;31m---------------------------------------------------------------------------[0m
[0;31mStdinNotImplementedError[0m                  Traceback (most recent call last)
Cell [0;32mIn[5], line 3[0m
[1;32m      1[0m [38;5;28;01mif[39;00m [38;5;129;01mnot[39;00m SETUP_COMPLETE:
[1;32m      2[0m     uow [38;5;241m=[39m container[38;5;241m.[39mdal[38;5;241m.[39muow()
[0;32m----> 3[0m     [43muow[49m[38;5;241;43m.[39;49m[43mreset[49m[43m([49m[43m)[49m

File [0;32m~/projects/bcd/bcd/dal/repo/uow.py:100[0m, in [0;36mUoW.reset[0;34m(self)[0m
[1;32m     98[0m [38;5;250m[39m[38;5;124;03m"""Resets all repositories for the current mode."""[39;00m
[1;32m     99[0m msg [38;5;241m=[39m [38;5;124m"[39m[38;5;124mThis will restore all repositories in the current mode to their initial state. Proceed? [Y/N][39m[38;5;124m"[39m
[0;32m--> 100[0m proceed [38;5;241m=[39m [38;5;28;43minput[39;49m[43m([49m[43mmsg[49m[43m)[49m
[1;32m    101[0m [38;5;28;01mif[39;00m [38;5;124m"[39m[38;5;124my[39m[38;5;124m"[39m [38;5;129;01min[39;00m proceed[38;5;241m.[39mlower():
[1;32m    102[0m     [38;5;28mself[39m[38;5;241m.[39mimage_repo[38;5;241m.[39mdelete_by_mode()

File [0;32m~/anaconda3/envs/bcd/lib/python3.10/site-packages/ipykernel/kernelbase.py:1201[0m, in [0;36mKernel.raw_input[0;34m(self, prompt)[0m
[1;32m   1199[0m [38;5;28;01mif[39;00m [38;5;129;01mnot[39;00m [38;5;28mself[39m[38;5;241m.[39m_allow_stdin:
[1;32m   1200[0m     msg [38;5;241m=[39m [38;5;124m"[39m[38;5;124mraw_input was called, but this frontend does not support input requests.[39m[38;5;124m"[39m
[0;32m-> 1201[0m     [38;5;28;01mraise[39;00m StdinNotImplementedError(msg)
[1;32m   1202[0m [38;5;28;01mreturn[39;00m [38;5;28mself[39m[38;5;241m.[39m_input_request(
[1;32m   1203[0m     [38;5;28mstr[39m(prompt),
[1;32m   1204[0m     [38;5;28mself[39m[38;5;241m.[39m_parent_ident[[38;5;124m"[39m[38;5;124mshell[39m[38;5;124m"[39m],
[1;32m   1205[0m     [38;5;28mself[39m[38;5;241m.[39mget_parent([38;5;124m"[39m[38;5;124mshell[39m[38;5;124m"[39m),
[1;32m   1206[0m     password[38;5;241m=[39m[38;5;28;01mFalse[39;00m,
[1;32m   1207[0m )

[0;31mStdinNotImplementedError[0m: raw_input was called, but this frontend does not support input requests.
StdinNotImplementedError: raw_input was called, but this frontend does not support input requests.

