Traceback (most recent call last):
  File "/home/john/anaconda3/envs/bcd/lib/python3.10/site-packages/jupyter_cache/executors/utils.py", line 58, in single_nb_execution
    executenb(
  File "/home/john/anaconda3/envs/bcd/lib/python3.10/site-packages/nbclient/client.py", line 1204, in execute
    return NotebookClient(nb=nb, resources=resources, km=km, **kwargs).execute()
  File "/home/john/anaconda3/envs/bcd/lib/python3.10/site-packages/nbclient/util.py", line 84, in wrapped
    return just_run(coro(*args, **kwargs))
  File "/home/john/anaconda3/envs/bcd/lib/python3.10/site-packages/nbclient/util.py", line 62, in just_run
    return loop.run_until_complete(coro)
  File "/home/john/anaconda3/envs/bcd/lib/python3.10/asyncio/base_events.py", line 649, in run_until_complete
    return future.result()
  File "/home/john/anaconda3/envs/bcd/lib/python3.10/site-packages/nbclient/client.py", line 663, in async_execute
    await self.async_execute_cell(
  File "/home/john/anaconda3/envs/bcd/lib/python3.10/site-packages/nbclient/client.py", line 965, in async_execute_cell
    await self._check_raise_for_error(cell, cell_index, exec_reply)
  File "/home/john/anaconda3/envs/bcd/lib/python3.10/site-packages/nbclient/client.py", line 862, in _check_raise_for_error
    raise CellExecutionError.from_cell_and_msg(cell, exec_reply_content)
nbclient.exceptions.CellExecutionError: An error occurred while executing the following cell:
------------------
# obtain the original images
img = get_image(fp=FP_WHITE)
img_fft = transform_image(img)
fig = plot_images(img1=img,img2=img_fft)
glue("fft_uniform", fig)
------------------

[0;31m---------------------------------------------------------------------------[0m
[0;31merror[0m                                     Traceback (most recent call last)
Cell [0;32mIn[14], line 2[0m
[1;32m      1[0m [38;5;66;03m# obtain the original images[39;00m
[0;32m----> 2[0m img [38;5;241m=[39m [43mget_image[49m[43m([49m[43mfp[49m[38;5;241;43m=[39;49m[43mFP_WHITE[49m[43m)[49m
[1;32m      3[0m img_fft [38;5;241m=[39m transform_image(img)
[1;32m      4[0m fig [38;5;241m=[39m plot_images(img1[38;5;241m=[39mimg,img2[38;5;241m=[39mimg_fft)

Cell [0;32mIn[13], line 12[0m, in [0;36mget_image[0;34m(fp, size)[0m
[1;32m     10[0m [38;5;28;01mdef[39;00m [38;5;21mget_image[39m(fp: [38;5;28mstr[39m, size: [38;5;28mint[39m [38;5;241m=[39m [38;5;241m200[39m):
[1;32m     11[0m     img [38;5;241m=[39m cv2[38;5;241m.[39mimread(fp, cv2[38;5;241m.[39mIMREAD_GRAYSCALE)
[0;32m---> 12[0m     [38;5;28;01mreturn[39;00m [43mcv2[49m[38;5;241;43m.[39;49m[43mresize[49m[43m([49m[43mimg[49m[43m,[49m[43m [49m[43m([49m[43msize[49m[43m,[49m[43msize[49m[43m)[49m[43m)[49m

[0;31merror[0m: OpenCV(4.8.1) /io/opencv/modules/imgproc/src/resize.cpp:4062: error: (-215:Assertion failed) !ssize.empty() in function 'resize'

error: OpenCV(4.8.1) /io/opencv/modules/imgproc/src/resize.cpp:4062: error: (-215:Assertion failed) !ssize.empty() in function 'resize'


