Traceback (most recent call last):
  File "/home/john/anaconda3/envs/bcd/lib/python3.10/site-packages/jupyter_cache/executors/utils.py", line 58, in single_nb_execution
    executenb(
  File "/home/john/anaconda3/envs/bcd/lib/python3.10/site-packages/nbclient/client.py", line 1204, in execute
    return NotebookClient(nb=nb, resources=resources, km=km, **kwargs).execute()
  File "/home/john/anaconda3/envs/bcd/lib/python3.10/site-packages/nbclient/util.py", line 84, in wrapped
    return just_run(coro(*args, **kwargs))
  File "/home/john/anaconda3/envs/bcd/lib/python3.10/site-packages/nbclient/util.py", line 62, in just_run
    return loop.run_until_complete(coro)
  File "/home/john/anaconda3/envs/bcd/lib/python3.10/asyncio/base_events.py", line 649, in run_until_complete
    return future.result()
  File "/home/john/anaconda3/envs/bcd/lib/python3.10/site-packages/nbclient/client.py", line 663, in async_execute
    await self.async_execute_cell(
  File "/home/john/anaconda3/envs/bcd/lib/python3.10/site-packages/nbclient/client.py", line 965, in async_execute_cell
    await self._check_raise_for_error(cell, cell_index, exec_reply)
  File "/home/john/anaconda3/envs/bcd/lib/python3.10/site-packages/nbclient/client.py", line 862, in _check_raise_for_error
    raise CellExecutionError.from_cell_and_msg(cell, exec_reply_content)
nbclient.exceptions.CellExecutionError: An error occurred while executing the following cell:
------------------
import os
if 'jbook' in os.getcwd():
    os.chdir(os.path.abspath(os.path.join("../../../..")))

import numpy as np
import cv2
import matplotlib.pyplot as plt
from bcd.utils.image import convert_uint8
from myst_nb import glue

img1 = "data/image/2_exp/train/benign/2a44122c-f831-4220-95a8-408bcafcf2ce.png"
img2 = "data/image/2_exp/train/benign/3f72309d-7cd9-4e30-ae81-073adb541bcd.png"
img3 = "data/image/2_exp/train/benign/97556037-b959-4395-830b-380dcac2d58e.png"
img4 = "data/image/2_exp/train/malignant/6cdf46d8-596b-47ab-a428-c8769733c93c.png"

img1 = cv2.imread(img1, cv2.IMREAD_GRAYSCALE)
img2 = cv2.imread(img2, cv2.IMREAD_GRAYSCALE)
img3 = cv2.imread(img3, cv2.IMREAD_GRAYSCALE)
img4 = cv2.imread(img4, cv2.IMREAD_GRAYSCALE)

img1 = convert_uint8(img1)
img2 = convert_uint8(img2)
img3 = convert_uint8(img3)
img4 = convert_uint8(img4)

fig, axes = plt.subplots(nrows=1, ncols=4, figsize=(12,6))
_ = axes[0].imshow(img1, cmap='gray', aspect='auto')
_ = axes[1].imshow(img2, cmap='gray',aspect='auto')
_ = axes[2].imshow(img3, cmap='gray',aspect='auto')
_ = axes[3].imshow(img4, cmap='gray',aspect='auto')

labels = np.array(["(a)", "(b)", "(c)", "(d)"])
for i in range(4):
    _ = axes[i].set_xlabel(labels[i,j])
    _ = axes[i].set_xticks([])
    _ = axes[i].set_yticks([])


plt.tight_layout()

glue("artifacts", fig)
------------------

[0;31m---------------------------------------------------------------------------[0m
[0;31mNameError[0m                                 Traceback (most recent call last)
Cell [0;32mIn[1], line 34[0m
[1;32m     32[0m labels [38;5;241m=[39m np[38;5;241m.[39marray([[38;5;124m"[39m[38;5;124m(a)[39m[38;5;124m"[39m, [38;5;124m"[39m[38;5;124m(b)[39m[38;5;124m"[39m, [38;5;124m"[39m[38;5;124m(c)[39m[38;5;124m"[39m, [38;5;124m"[39m[38;5;124m(d)[39m[38;5;124m"[39m])
[1;32m     33[0m [38;5;28;01mfor[39;00m i [38;5;129;01min[39;00m [38;5;28mrange[39m([38;5;241m4[39m):
[0;32m---> 34[0m     _ [38;5;241m=[39m axes[i][38;5;241m.[39mset_xlabel(labels[i,[43mj[49m])
[1;32m     35[0m     _ [38;5;241m=[39m axes[i][38;5;241m.[39mset_xticks([])
[1;32m     36[0m     _ [38;5;241m=[39m axes[i][38;5;241m.[39mset_yticks([])

[0;31mNameError[0m: name 'j' is not defined
NameError: name 'j' is not defined

