Traceback (most recent call last):
  File "/home/john/anaconda3/envs/bcd/lib/python3.10/site-packages/jupyter_cache/executors/utils.py", line 58, in single_nb_execution
    executenb(
  File "/home/john/anaconda3/envs/bcd/lib/python3.10/site-packages/nbclient/client.py", line 1204, in execute
    return NotebookClient(nb=nb, resources=resources, km=km, **kwargs).execute()
  File "/home/john/anaconda3/envs/bcd/lib/python3.10/site-packages/nbclient/util.py", line 84, in wrapped
    return just_run(coro(*args, **kwargs))
  File "/home/john/anaconda3/envs/bcd/lib/python3.10/site-packages/nbclient/util.py", line 62, in just_run
    return loop.run_until_complete(coro)
  File "/home/john/anaconda3/envs/bcd/lib/python3.10/asyncio/base_events.py", line 649, in run_until_complete
    return future.result()
  File "/home/john/anaconda3/envs/bcd/lib/python3.10/site-packages/nbclient/client.py", line 663, in async_execute
    await self.async_execute_cell(
  File "/home/john/anaconda3/envs/bcd/lib/python3.10/site-packages/nbclient/client.py", line 965, in async_execute_cell
    await self._check_raise_for_error(cell, cell_index, exec_reply)
  File "/home/john/anaconda3/envs/bcd/lib/python3.10/site-packages/nbclient/client.py", line 862, in _check_raise_for_error
    raise CellExecutionError.from_cell_and_msg(cell, exec_reply_content)
nbclient.exceptions.CellExecutionError: An error occurred while executing the following cell:
------------------
import os
if 'jbook' in os.getcwd():
    os.chdir(os.path.abspath(os.path.join("../../../..")))

import os
import cv2
import matplotlib.pyplot as plt
from myst_nb import glue

r, bm1 = cv2.threshold(img1, 127, 255, cv2.THRESH_BINARY)
r, bm2 = cv2.threshold(img2, 127, 255, cv2.THRESH_BINARY)
r, bm3 = cv2.threshold(img3, 127, 255, cv2.THRESH_BINARY)
r, bm4 = cv2.threshold(img4, 127, 255, cv2.THRESH_BINARY)

fig, axes = plt.subplots(nrows=1, ncols=4, figsize=(12,6))
_ = axes[0].imshow(bm1, cmap='gray', aspect='auto')
_ = axes[1].imshow(bm2, cmap='gray',aspect='auto')
_ = axes[2].imshow(bm3, cmap='gray',aspect='auto')
_ = axes[3].imshow(bm4, cmap='gray',aspect='auto')

plt.tight_layout()

glue("bm1", fig)
------------------

[0;31m---------------------------------------------------------------------------[0m
[0;31mNameError[0m                                 Traceback (most recent call last)
Cell [0;32mIn[1], line 10[0m
[1;32m      7[0m [38;5;28;01mimport[39;00m [38;5;21;01mmatplotlib[39;00m[38;5;21;01m.[39;00m[38;5;21;01mpyplot[39;00m [38;5;28;01mas[39;00m [38;5;21;01mplt[39;00m
[1;32m      8[0m [38;5;28;01mfrom[39;00m [38;5;21;01mmyst_nb[39;00m [38;5;28;01mimport[39;00m glue
[0;32m---> 10[0m r, bm1 [38;5;241m=[39m cv2[38;5;241m.[39mthreshold([43mimg1[49m, [38;5;241m127[39m, [38;5;241m255[39m, cv2[38;5;241m.[39mTHRESH_BINARY)
[1;32m     11[0m r, bm2 [38;5;241m=[39m cv2[38;5;241m.[39mthreshold(img2, [38;5;241m127[39m, [38;5;241m255[39m, cv2[38;5;241m.[39mTHRESH_BINARY)
[1;32m     12[0m r, bm3 [38;5;241m=[39m cv2[38;5;241m.[39mthreshold(img3, [38;5;241m127[39m, [38;5;241m255[39m, cv2[38;5;241m.[39mTHRESH_BINARY)

[0;31mNameError[0m: name 'img1' is not defined
NameError: name 'img1' is not defined

