Traceback (most recent call last):
  File "/home/john/anaconda3/envs/bcd/lib/python3.10/site-packages/jupyter_cache/executors/utils.py", line 58, in single_nb_execution
    executenb(
  File "/home/john/anaconda3/envs/bcd/lib/python3.10/site-packages/nbclient/client.py", line 1204, in execute
    return NotebookClient(nb=nb, resources=resources, km=km, **kwargs).execute()
  File "/home/john/anaconda3/envs/bcd/lib/python3.10/site-packages/nbclient/util.py", line 84, in wrapped
    return just_run(coro(*args, **kwargs))
  File "/home/john/anaconda3/envs/bcd/lib/python3.10/site-packages/nbclient/util.py", line 62, in just_run
    return loop.run_until_complete(coro)
  File "/home/john/anaconda3/envs/bcd/lib/python3.10/asyncio/base_events.py", line 649, in run_until_complete
    return future.result()
  File "/home/john/anaconda3/envs/bcd/lib/python3.10/site-packages/nbclient/client.py", line 663, in async_execute
    await self.async_execute_cell(
  File "/home/john/anaconda3/envs/bcd/lib/python3.10/site-packages/nbclient/client.py", line 965, in async_execute_cell
    await self._check_raise_for_error(cell, cell_index, exec_reply)
  File "/home/john/anaconda3/envs/bcd/lib/python3.10/site-packages/nbclient/client.py", line 862, in _check_raise_for_error
    raise CellExecutionError.from_cell_and_msg(cell, exec_reply_content)
nbclient.exceptions.CellExecutionError: An error occurred while executing the following cell:
------------------
import os
if 'jbook' in os.getcwd():
    os.chdir(os.path.abspath(os.path.join("../../../..")))
import cv2
import matplotlib.pyplot as plt
import numpy as np
from bcd.utils.image import convert_uint8

FP_WHITE = "jbook/figures/frequency_white.jpg"
FP_HLINE = "jbook/figures/frequency_hline.png"
FP_VLINE = "jbook/figures/frequency_vline.png"

def get_image(fp: str, size: int = 200):
    img = cv2.imread(fp, cv2.IMREAD_GRAYSCALE)
    return cv2.resize(img, (size,size))

def transform_image(img):
    # Compute fourier transformation
    img_fft = np.fft.fft2(img)
    # Shift the zero-frequency to the center
    img_shifted = np.fft.fftshift(img_fft)
    # Compute amplitude
    img_amp = np.abs(img_shifted)
    img_amp = np.clip(img_amp, a_min=0, a_max=50000)
    return img_amp

def plot_images(img1, img2, size=(12,6)):
    fig, axes = plt.subplots(nrows=1, ncols=2, figsize=size)
    _ = axes[0].imshow(img1, cmap='gray')
    _ = axes[1].imshow(img2, cmap='gray')

    for i in range(2):
        _ = axes[i].set_xticks([])
        _ = axes[i].set_yticks([])
    plt.tight_layout()
    return fig

# obtain the original images
img = get_image(fp=FP_WHITE)
img_fft = transform_image(img)
fig = plot_images(img1=img,img2=img_fft)
glue("fft_uniform", fig)
------------------

[0;31m---------------------------------------------------------------------------[0m
[0;31mNameError[0m                                 Traceback (most recent call last)
Cell [0;32mIn[1], line 42[0m
[1;32m     40[0m img_fft [38;5;241m=[39m transform_image(img)
[1;32m     41[0m fig [38;5;241m=[39m plot_images(img1[38;5;241m=[39mimg,img2[38;5;241m=[39mimg_fft)
[0;32m---> 42[0m [43mglue[49m([38;5;124m"[39m[38;5;124mfft_uniform[39m[38;5;124m"[39m, fig)

[0;31mNameError[0m: name 'glue' is not defined
NameError: name 'glue' is not defined

